<sdf version='1.7'>
  <model name='jobot'>
    <link name='base_footprint'>
      <inertial>
        <pose>0 0 0.059 0 -0 0</pose>
        <mass>1</mass>
        <inertia>
          <ixx>0.00290833</ixx>
          <ixy>0</ixy>
          <ixz>0</ixz>
          <iyy>0.00290833</iyy>
          <iyz>0</iyz>
          <izz>0.005</izz>
        </inertia>
      </inertial>
      <collision name='base_footprint_fixed_joint_lump__base_link_collision'>
        <pose>0 0 0.059 0 -0 0</pose>
        <geometry>
          <cylinder>
            <length>0.07</length>
            <radius>0.1</radius>
          </cylinder>
        </geometry>
        <surface>
          <contact>
            <ode/>
          </contact>
          <friction>
            <ode/>
          </friction>
        </surface>
      </collision>
      <collision name='base_footprint_fixed_joint_lump__camera_link_collision_1'>
        <pose>0.12 0 0.099 0 -0 0</pose>
        <geometry>
          <box>
            <size>0.012 0.132 0.02</size>
          </box>
        </geometry>
      </collision>
      <visual name='base_footprint_fixed_joint_lump__base_link_visual'>
        <pose>0 0 0.059 0 -0 0</pose>
        <geometry>
          <cylinder>
            <length>0.07</length>
            <radius>0.1</radius>
          </cylinder>
        </geometry>
        <material>
          <script>
            <name>Gazebo/Yellow</name>
            <uri>file://media/materials/scripts/gazebo.material</uri>
          </script>
        </material>
      </visual>
      <visual name='base_footprint_fixed_joint_lump__camera_link_visual_1'>
        <pose>0.12 0 0.099 1.57 -0 1.57</pose>
        <geometry>
          <box>
            <size>0.012 0.132 0.02</size>
          </box>
        </geometry>
      </visual>
      <sensor name='camera' type='depth'>
        <always_on>1</always_on>
        <visualize>1</visualize>
        <update_rate>20</update_rate>
        <camera name='intel_realsense_r200'>
          <horizontal_fov>1.0472</horizontal_fov>
          <image>
            <format>R8G8B8</format>
            <width>640</width>
            <height>480</height>
          </image>
          <clip>
            <near>0.02</near>
            <far>300</far>
          </clip>
          <noise>
            <type>gaussian</type>
            <mean>0</mean>
            <stddev>0.007</stddev>
          </noise>
        </camera>
        <plugin name='camera_controller' filename='libgazebo_ros_camera.so'>
          <frameName>camera_rgb_optical_frame</frameName>
        </plugin>
        <pose>0.125 0.018 0.112 -1.5708 -0 -1.5708</pose>
        <frameName>camera_rgb_optical_frame</frameName>
      </sensor>
    </link>
    <joint name='back_top_caster_joint' type='revolute'>
      <pose relative_to='base_footprint'>-0.08 0 0.024 0 -0 0</pose>
      <parent>base_footprint</parent>
      <child>back_top_link</child>
      <axis>
        <xyz>0 0 1</xyz>
        <limit>
          <lower>-1e+16</lower>
          <upper>1e+16</upper>
        </limit>
        <dynamics>
          <spring_reference>0</spring_reference>
          <spring_stiffness>0</spring_stiffness>
        </dynamics>
      </axis>
    </joint>
    <link name='back_top_link'>
      <pose relative_to='back_top_caster_joint'>0 0 0 0 -0 0</pose>
      <inertial>
        <pose>0 0 0 0 -0 0</pose>
        <mass>0.01</mass>
        <inertia>
          <ixx>3.60052e-07</ixx>
          <ixy>0</ixy>
          <ixz>0</ixz>
          <iyy>3.60052e-07</iyy>
          <iyz>0</iyz>
          <izz>7.2e-07</izz>
        </inertia>
      </inertial>
      <collision name='back_top_link_collision'>
        <pose>0 0 0 0 -0 0</pose>
        <geometry>
          <cylinder>
            <length>0.00025</length>
            <radius>0.012</radius>
          </cylinder>
        </geometry>
      </collision>
      <visual name='back_top_link_visual'>
        <pose>0 0 0 0 -0 0</pose>
        <geometry>
          <cylinder>
            <length>0.00025</length>
            <radius>0.012</radius>
          </cylinder>
        </geometry>
      </visual>
    </link>
    <joint name='back_caster_joint' type='revolute'>
      <pose relative_to='back_top_link'>0.012 0 -0.012 0 -0 0</pose>
      <parent>back_top_link</parent>
      <child>back_caster_link</child>
      <axis>
        <xyz>0 1 0</xyz>
        <limit>
          <lower>-1e+16</lower>
          <upper>1e+16</upper>
        </limit>
        <dynamics>
          <spring_reference>0</spring_reference>
          <spring_stiffness>0</spring_stiffness>
        </dynamics>
      </axis>
    </joint>
    <link name='back_caster_link'>
      <pose relative_to='back_caster_joint'>0 0 0 0 -0 0</pose>
      <inertial>
        <pose>0 0 0 0 -0 0</pose>
        <mass>0.2</mass>
        <inertia>
          <ixx>7.61667e-06</ixx>
          <ixy>0</ixy>
          <ixz>0</ixz>
          <iyy>7.61667e-06</iyy>
          <iyz>0</iyz>
          <izz>1.44e-05</izz>
        </inertia>
      </inertial>
      <collision name='back_caster_link_collision'>
        <pose>0 0 0 1.5708 -0 0</pose>
        <geometry>
          <cylinder>
            <length>0.005</length>
            <radius>0.012</radius>
          </cylinder>
        </geometry>
        <surface>
          <contact>
            <ode/>
          </contact>
          <friction>
            <ode/>
          </friction>
        </surface>
      </collision>
      <visual name='back_caster_link_visual'>
        <pose>0 0 0 1.5708 -0 0</pose>
        <geometry>
          <cylinder>
            <length>0.005</length>
            <radius>0.012</radius>
          </cylinder>
        </geometry>
        <material>
          <script>
            <name>Gazebo/Black</name>
            <uri>file://media/materials/scripts/gazebo.material</uri>
          </script>
        </material>
      </visual>
    </link>
    <joint name='front_top_caster_joint' type='revolute'>
      <pose relative_to='base_footprint'>0.08 0 0.024 0 -0 0</pose>
      <parent>base_footprint</parent>
      <child>front_top_link</child>
      <axis>
        <xyz>0 0 1</xyz>
        <limit>
          <lower>-1e+16</lower>
          <upper>1e+16</upper>
        </limit>
        <dynamics>
          <spring_reference>0</spring_reference>
          <spring_stiffness>0</spring_stiffness>
        </dynamics>
      </axis>
    </joint>
    <link name='front_top_link'>
      <pose relative_to='front_top_caster_joint'>0 0 0 0 -0 0</pose>
      <inertial>
        <pose>0 0 0 0 -0 0</pose>
        <mass>0.01</mass>
        <inertia>
          <ixx>3.60052e-07</ixx>
          <ixy>0</ixy>
          <ixz>0</ixz>
          <iyy>3.60052e-07</iyy>
          <iyz>0</iyz>
          <izz>7.2e-07</izz>
        </inertia>
      </inertial>
      <collision name='front_top_link_collision'>
        <pose>0 0 0 0 -0 0</pose>
        <geometry>
          <cylinder>
            <length>0.00025</length>
            <radius>0.012</radius>
          </cylinder>
        </geometry>
      </collision>
      <visual name='front_top_link_visual'>
        <pose>0 0 0 0 -0 0</pose>
        <geometry>
          <cylinder>
            <length>0.00025</length>
            <radius>0.012</radius>
          </cylinder>
        </geometry>
      </visual>
    </link>
    <joint name='front_caster_joint' type='revolute'>
      <pose relative_to='front_top_link'>0.012 0 -0.012 0 -0 0</pose>
      <parent>front_top_link</parent>
      <child>front_caster_link</child>
      <axis>
        <xyz>0 1 0</xyz>
        <limit>
          <lower>-1e+16</lower>
          <upper>1e+16</upper>
        </limit>
        <dynamics>
          <spring_reference>0</spring_reference>
          <spring_stiffness>0</spring_stiffness>
        </dynamics>
      </axis>
    </joint>
    <link name='front_caster_link'>
      <pose relative_to='front_caster_joint'>0 0 0 0 -0 0</pose>
      <inertial>
        <pose>0 0 0 0 -0 0</pose>
        <mass>0.2</mass>
        <inertia>
          <ixx>7.61667e-06</ixx>
          <ixy>0</ixy>
          <ixz>0</ixz>
          <iyy>7.61667e-06</iyy>
          <iyz>0</iyz>
          <izz>1.44e-05</izz>
        </inertia>
      </inertial>
      <collision name='front_caster_link_collision'>
        <pose>0 0 0 1.5708 -0 0</pose>
        <geometry>
          <cylinder>
            <length>0.005</length>
            <radius>0.012</radius>
          </cylinder>
        </geometry>
        <surface>
          <contact>
            <ode/>
          </contact>
          <friction>
            <ode/>
          </friction>
        </surface>
      </collision>
      <visual name='front_caster_link_visual'>
        <pose>0 0 0 1.5708 -0 0</pose>
        <geometry>
          <cylinder>
            <length>0.005</length>
            <radius>0.012</radius>
          </cylinder>
        </geometry>
        <material>
          <script>
            <name>Gazebo/Black</name>
            <uri>file://media/materials/scripts/gazebo.material</uri>
          </script>
        </material>
      </visual>
    </link>
    <joint name='left_wheel_joint' type='revolute'>
      <pose relative_to='base_footprint'>0 0.1125 0.04 0 -0 0</pose>
      <parent>base_footprint</parent>
      <child>left_wheel_link</child>
      <axis>
        <xyz>0 1 0</xyz>
        <limit>
          <lower>-1e+16</lower>
          <upper>1e+16</upper>
        </limit>
        <dynamics>
          <spring_reference>0</spring_reference>
          <spring_stiffness>0</spring_stiffness>
        </dynamics>
      </axis>
    </joint>
    <link name='left_wheel_link'>
      <pose relative_to='left_wheel_joint'>0 0 0 0 -0 0</pose>
      <inertial>
        <pose>0 0 0 0 -0 0</pose>
        <mass>0.2</mass>
        <inertia>
          <ixx>9.04167e-05</ixx>
          <ixy>0</ixy>
          <ixz>0</ixz>
          <iyy>9.04167e-05</iyy>
          <iyz>0</iyz>
          <izz>0.00016</izz>
        </inertia>
      </inertial>
      <collision name='left_wheel_link_collision'>
        <pose>0 0 0 1.5708 -0 0</pose>
        <geometry>
          <cylinder>
            <length>0.025</length>
            <radius>0.04</radius>
          </cylinder>
        </geometry>
        <surface>
          <contact>
            <ode/>
          </contact>
          <friction>
            <ode>
              <mu>100000</mu>
              <mu2>100000</mu2>
            </ode>
          </friction>
        </surface>
      </collision>
      <visual name='left_wheel_link_visual'>
        <pose>0 0 0 1.5708 -0 0</pose>
        <geometry>
          <cylinder>
            <length>0.025</length>
            <radius>0.04</radius>
          </cylinder>
        </geometry>
        <material>
          <script>
            <name>Gazebo/Gray</name>
            <uri>file://media/materials/scripts/gazebo.material</uri>
          </script>
        </material>
      </visual>
    </link>
    <joint name='right_wheel_joint' type='revolute'>
      <pose relative_to='base_footprint'>0 -0.1125 0.04 0 -0 0</pose>
      <parent>base_footprint</parent>
      <child>right_wheel_link</child>
      <axis>
        <xyz>0 1 0</xyz>
        <limit>
          <lower>-1e+16</lower>
          <upper>1e+16</upper>
        </limit>
        <dynamics>
          <spring_reference>0</spring_reference>
          <spring_stiffness>0</spring_stiffness>
        </dynamics>
      </axis>
    </joint>
    <link name='right_wheel_link'>
      <pose relative_to='right_wheel_joint'>0 0 0 0 -0 0</pose>
      <inertial>
        <pose>0 0 0 0 -0 0</pose>
        <mass>0.2</mass>
        <inertia>
          <ixx>9.04167e-05</ixx>
          <ixy>0</ixy>
          <ixz>0</ixz>
          <iyy>9.04167e-05</iyy>
          <iyz>0</iyz>
          <izz>0.00016</izz>
        </inertia>
      </inertial>
      <collision name='right_wheel_link_collision'>
        <pose>0 0 0 1.5708 -0 0</pose>
        <geometry>
          <cylinder>
            <length>0.025</length>
            <radius>0.04</radius>
          </cylinder>
        </geometry>
        <surface>
          <contact>
            <ode/>
          </contact>
          <friction>
            <ode>
              <mu>100000</mu>
              <mu2>100000</mu2>
            </ode>
          </friction>
        </surface>
      </collision>
      <visual name='right_wheel_link_visual'>
        <pose>0 0 0 1.5708 -0 0</pose>
        <geometry>
          <cylinder>
            <length>0.025</length>
            <radius>0.04</radius>
          </cylinder>
        </geometry>
        <material>
          <script>
            <name>Gazebo/Gray</name>
            <uri>file://media/materials/scripts/gazebo.material</uri>
          </script>
        </material>
      </visual>
    </link>
    <static>0</static>
    <plugin name='differential_drive_controller' filename='libgazebo_ros_diff_drive.so'>
      <update_rate>30</update_rate>
      <left_joint>left_wheel_joint</left_joint>
      <right_joint>right_wheel_joint</right_joint>
      <wheel_separation>0.225</wheel_separation>
      <wheel_diameter>0.08</wheel_diameter>
      <max_wheel_torque>10</max_wheel_torque>
      <max_wheel_acceleration>1.0</max_wheel_acceleration>
      <command_topic>cmd_vel</command_topic>
      <publish_odom>1</publish_odom>
      <publish_odom_tf>1</publish_odom_tf>
      <publish_wheel_tf>1</publish_wheel_tf>
      <odometry_topic>odom</odometry_topic>
      <odometry_frame>odom</odometry_frame>
      <robot_base_frame>base_footprint</robot_base_frame>
      <odometry_source>1</odometry_source>
    </plugin>
  </model>
</sdf>
